time: 2014-09-04 15:36:21.547639Z
tags: worker-0
test: workloadmgr.tests.test_wsgi.ExceptionTest.test_exception_with_none_code_throws_500
time: 2014-09-04 15:36:21.629534Z
successful: workloadmgr.tests.test_wsgi.ExceptionTest.test_exception_with_none_code_throws_500 [ multipart
Content-Type: text/plain;charset="utf8"
pythonlogging:''
346
Caught error: 
Traceback (most recent call last):
  File "workloadmgr/api/middleware/fault.py", line 60, in __call__
    return req.get_response(self.application)
  File "/usr/lib/python2.7/dist-packages/webob/request.py", line 1296, in send
    application, catch_exc_info=False)
  File "/usr/lib/python2.7/dist-packages/webob/request.py", line 1260, in call_application
    app_iter = application(self.environ, start_response)
  File "/usr/lib/python2.7/dist-packages/webob/dec.py", line 130, in __call__
    resp = self.call_func(req, *args, **self.kwargs)
  File "/usr/lib/python2.7/dist-packages/webob/dec.py", line 195, in call_func
    return self.func(req, *args, **kwargs)
  File "workloadmgr/tests/test_wsgi.py", line 264, in fail
    raise ExceptionWithNoneCode()
ExceptionWithNoneCode
http://localhost/ returned with HTTP 500
0
]
tags: -worker-0
time: 2014-09-04 15:36:21.629950Z
tags: worker-0
test: workloadmgr.tests.test_wsgi.ExceptionTest.test_non_workloadmgr_exception_mapping
time: 2014-09-04 15:36:21.635322Z
successful: workloadmgr.tests.test_wsgi.ExceptionTest.test_non_workloadmgr_exception_mapping [ multipart
Content-Type: text/plain;charset="utf8"
pythonlogging:''
364
Caught error: Expectation failed
Traceback (most recent call last):
  File "workloadmgr/api/middleware/fault.py", line 60, in __call__
    return req.get_response(self.application)
  File "/usr/lib/python2.7/dist-packages/webob/request.py", line 1296, in send
    application, catch_exc_info=False)
  File "/usr/lib/python2.7/dist-packages/webob/request.py", line 1260, in call_application
    app_iter = application(self.environ, start_response)
  File "/usr/lib/python2.7/dist-packages/webob/dec.py", line 130, in __call__
    resp = self.call_func(req, *args, **self.kwargs)
  File "/usr/lib/python2.7/dist-packages/webob/dec.py", line 195, in call_func
    return self.func(req, *args, **kwargs)
  File "workloadmgr/tests/test_wsgi.py", line 227, in fail
    raise exception_type(msg)
ExceptionWithCode: Expectation failed
http://localhost/ returned with HTTP 417
0
]
tags: -worker-0
time: 2014-09-04 15:36:21.635641Z
tags: worker-0
test: workloadmgr.tests.test_wsgi.ExceptionTest.test_non_workloadmgr_notfound_exception_mapping
time: 2014-09-04 15:36:21.640602Z
successful: workloadmgr.tests.test_wsgi.ExceptionTest.test_non_workloadmgr_notfound_exception_mapping [ multipart
Content-Type: text/plain;charset="utf8"
pythonlogging:''
350
Caught error: NotFound
Traceback (most recent call last):
  File "workloadmgr/api/middleware/fault.py", line 60, in __call__
    return req.get_response(self.application)
  File "/usr/lib/python2.7/dist-packages/webob/request.py", line 1296, in send
    application, catch_exc_info=False)
  File "/usr/lib/python2.7/dist-packages/webob/request.py", line 1260, in call_application
    app_iter = application(self.environ, start_response)
  File "/usr/lib/python2.7/dist-packages/webob/dec.py", line 130, in __call__
    resp = self.call_func(req, *args, **self.kwargs)
  File "/usr/lib/python2.7/dist-packages/webob/dec.py", line 195, in call_func
    return self.func(req, *args, **kwargs)
  File "workloadmgr/tests/test_wsgi.py", line 227, in fail
    raise exception_type(msg)
ExceptionWithCode: NotFound
http://localhost/ returned with HTTP 404
0
]
tags: -worker-0
time: 2014-09-04 15:36:21.640903Z
tags: worker-0
test: workloadmgr.tests.test_wsgi.ExceptionTest.test_quota_error_mapping
time: 2014-09-04 15:36:21.645632Z
successful: workloadmgr.tests.test_wsgi.ExceptionTest.test_quota_error_mapping [ multipart
Content-Type: text/plain;charset="utf8"
pythonlogging:''
353
Caught error: too many used
Traceback (most recent call last):
  File "workloadmgr/api/middleware/fault.py", line 60, in __call__
    return req.get_response(self.application)
  File "/usr/lib/python2.7/dist-packages/webob/request.py", line 1296, in send
    application, catch_exc_info=False)
  File "/usr/lib/python2.7/dist-packages/webob/request.py", line 1260, in call_application
    app_iter = application(self.environ, start_response)
  File "/usr/lib/python2.7/dist-packages/webob/dec.py", line 130, in __call__
    resp = self.call_func(req, *args, **self.kwargs)
  File "/usr/lib/python2.7/dist-packages/webob/dec.py", line 195, in call_func
    return self.func(req, *args, **kwargs)
  File "workloadmgr/tests/test_wsgi.py", line 227, in fail
    raise exception_type(msg)
QuotaError: too many used
http://localhost/ returned with HTTP 413
0
]
tags: -worker-0
time: 2014-09-04 15:36:21.645924Z
tags: worker-0
test: workloadmgr.tests.test_wsgi.ExceptionTest.test_safe_exceptions_are_described_in_faults
time: 2014-09-04 15:36:21.652969Z
successful: workloadmgr.tests.test_wsgi.ExceptionTest.test_safe_exceptions_are_described_in_faults [ multipart
Content-Type: text/plain;charset="utf8"
pythonlogging:''
376
Caught error: some explanation
Traceback (most recent call last):
  File "workloadmgr/api/middleware/fault.py", line 60, in __call__
    return req.get_response(self.application)
  File "/usr/lib/python2.7/dist-packages/webob/request.py", line 1296, in send
    application, catch_exc_info=False)
  File "/usr/lib/python2.7/dist-packages/webob/request.py", line 1260, in call_application
    app_iter = application(self.environ, start_response)
  File "/usr/lib/python2.7/dist-packages/webob/dec.py", line 130, in __call__
    resp = self.call_func(req, *args, **self.kwargs)
  File "/usr/lib/python2.7/dist-packages/webob/dec.py", line 195, in call_func
    return self.func(req, *args, **kwargs)
  File "workloadmgr/tests/test_wsgi.py", line 207, in fail
    raise ExceptionWithSafety('some explanation')
ExceptionWithSafety: some explanation
http://localhost/ returned with HTTP 500
0
]
tags: -worker-0
time: 2014-09-04 15:36:21.653312Z
tags: worker-0
test: workloadmgr.tests.test_wsgi.ExceptionTest.test_unsafe_exceptions_are_not_described_in_faults
time: 2014-09-04 15:36:21.658062Z
successful: workloadmgr.tests.test_wsgi.ExceptionTest.test_unsafe_exceptions_are_not_described_in_faults [ multipart
Content-Type: text/plain;charset="utf8"
pythonlogging:''
376
Caught error: some explanation
Traceback (most recent call last):
  File "workloadmgr/api/middleware/fault.py", line 60, in __call__
    return req.get_response(self.application)
  File "/usr/lib/python2.7/dist-packages/webob/request.py", line 1296, in send
    application, catch_exc_info=False)
  File "/usr/lib/python2.7/dist-packages/webob/request.py", line 1260, in call_application
    app_iter = application(self.environ, start_response)
  File "/usr/lib/python2.7/dist-packages/webob/dec.py", line 130, in __call__
    resp = self.call_func(req, *args, **self.kwargs)
  File "/usr/lib/python2.7/dist-packages/webob/dec.py", line 195, in call_func
    return self.func(req, *args, **kwargs)
  File "workloadmgr/tests/test_wsgi.py", line 207, in fail
    raise ExceptionWithSafety('some explanation')
ExceptionWithSafety: some explanation
http://localhost/ returned with HTTP 500
0
]
tags: -worker-0
time: 2014-09-04 15:36:21.658358Z
tags: worker-0
test: workloadmgr.tests.test_wsgi.ExceptionTest.test_workloadmgr_exception_with_localized_explanation
time: 2014-09-04 15:36:21.663576Z
failure: workloadmgr.tests.test_wsgi.ExceptionTest.test_workloadmgr_exception_with_localized_explanation [ multipart
Content-Type: text/x-traceback;charset="utf8",language="python"
traceback
594
Traceback (most recent call last):
_StringException: Empty attachments:
  pythonlogging:''
  pythonlogging:''-1
  stderr
  stdout

Traceback (most recent call last):
  File "/usr/local/lib/python2.7/dist-packages/mock.py", line 1193, in patched
    arg = patching.__enter__()
  File "/usr/local/lib/python2.7/dist-packages/mock.py", line 1268, in __enter__
    original, local = self.get_original()
  File "/usr/local/lib/python2.7/dist-packages/mock.py", line 1242, in get_original
    "%s does not have the attribute %r" % (target, name)
AttributeError: <module 'workloadmgr.openstack.common.gettextutils' from 'workloadmgr/openstack/common/gettextutils.py'> does not have the attribute 'get_localized_message'

Traceback (most recent call last):
_StringException: Empty attachments:
  pythonlogging:''
  pythonlogging:''-1
  stderr
  stdout

Traceback (most recent call last):
  File "/usr/local/lib/python2.7/dist-packages/mock.py", line 1193, in patched
    arg = patching.__enter__()
  File "/usr/local/lib/python2.7/dist-packages/mock.py", line 1268, in __enter__
    original, local = self.get_original()
  File "/usr/local/lib/python2.7/dist-packages/mock.py", line 1242, in get_original
    "%s does not have the attribute %r" % (target, name)
AttributeError: <module 'workloadmgr.openstack.common.gettextutils' from 'workloadmgr/openstack/common/gettextutils.py'> does not have the attribute 'get_localized_message'

0
]
tags: -worker-0
time: 2014-09-04 15:36:21.663869Z
tags: worker-0
test: workloadmgr.tests.test_wsgi.TestLoaderNormalFilesystem.test_app_found
time: 2014-09-04 15:36:21.675767Z
successful: workloadmgr.tests.test_wsgi.TestLoaderNormalFilesystem.test_app_found [ multipart
]
tags: -worker-0
time: 2014-09-04 15:36:21.676028Z
tags: worker-0
test: workloadmgr.tests.test_wsgi.TestLoaderNormalFilesystem.test_app_not_found
time: 2014-09-04 15:36:21.681147Z
successful: workloadmgr.tests.test_wsgi.TestLoaderNormalFilesystem.test_app_not_found [ multipart
Content-Type: text/plain;charset="utf8"
pythonlogging:''
A7
No section 'non-existent app' (prefixed by 'app' or 'application' or 'composite' or 'composit' or 'pipeline' or 'filter-app') found in config /tmp/tmp8a_9hm/tmpE13cp9
0
]
tags: -worker-0
time: 2014-09-04 15:36:21.681451Z
tags: worker-0
test: workloadmgr.tests.test_wsgi.TestLoaderNormalFilesystem.test_config_found
time: 2014-09-04 15:36:21.685816Z
successful: workloadmgr.tests.test_wsgi.TestLoaderNormalFilesystem.test_config_found [ multipart
]
tags: -worker-0
time: 2014-09-04 15:36:21.686037Z
tags: worker-0
test: workloadmgr.tests.test_wsgi.TestLoaderNothingExists.test_config_not_found
time: 2014-09-04 15:36:21.690075Z
successful: workloadmgr.tests.test_wsgi.TestLoaderNothingExists.test_config_not_found [ multipart
]
tags: -worker-0
time: 2014-09-04 15:36:21.690290Z
tags: worker-0
test: workloadmgr.tests.test_wsgi.TestWSGIServer.test_app
time: 2014-09-04 15:36:21.697230Z
successful: workloadmgr.tests.test_wsgi.TestWSGIServer.test_app [ multipart
Content-Type: text/plain;charset="utf8"
pythonlogging:''
DA
Started test_app on 0.0.0.0:42399
(27382) wsgi starting up on http://0.0.0.0:42399/

(27382) accepted ('127.0.0.1', 50122)

127.0.0.1 - - [04/Sep/2014 11:36:21] "GET / HTTP/1.1" 200 136 0.000085

Stopping WSGI server.
0
]
tags: -worker-0
time: 2014-09-04 15:36:21.697537Z
tags: worker-0
test: workloadmgr.tests.test_wsgi.TestWSGIServer.test_app_using_ipv6_and_ssl
time: 2014-09-04 15:36:21.921903Z
failure: workloadmgr.tests.test_wsgi.TestWSGIServer.test_app_using_ipv6_and_ssl [ multipart
Content-Type: text/x-traceback;charset="utf8",language="python"
traceback
55E
Traceback (most recent call last):
_StringException: Empty attachments:
  pythonlogging:''
  pythonlogging:''-1
  stderr
  stdout

Traceback (most recent call last):
  File "workloadmgr/tests/test_wsgi.py", line 181, in test_app_using_ipv6_and_ssl
    server.start()
  File "workloadmgr/wsgi.py", line 191, in start
    backlog=backlog)
  File "workloadmgr/wsgi.py", line 141, in _get_socket
    family=family)
  File "/usr/local/lib/python2.7/dist-packages/eventlet/convenience.py", line 39, in listen
    sock.bind(addr)
  File "/usr/lib/python2.7/socket.py", line 224, in meth
    return getattr(self._sock,name)(*args)
gaierror: [Errno -9] Address family for hostname not supported

Traceback (most recent call last):
_StringException: Empty attachments:
  pythonlogging:''
  pythonlogging:''-1
  stderr
  stdout

Traceback (most recent call last):
  File "workloadmgr/tests/test_wsgi.py", line 181, in test_app_using_ipv6_and_ssl
    server.start()
  File "workloadmgr/wsgi.py", line 191, in start
    backlog=backlog)
  File "workloadmgr/wsgi.py", line 141, in _get_socket
    family=family)
  File "/usr/local/lib/python2.7/dist-packages/eventlet/convenience.py", line 39, in listen
    sock.bind(addr)
  File "/usr/lib/python2.7/socket.py", line 224, in meth
    return getattr(self._sock,name)(*args)
gaierror: [Errno -9] Address family for hostname not supported

0
]
tags: -worker-0
time: 2014-09-04 15:36:21.922227Z
tags: worker-0
test: workloadmgr.tests.test_wsgi.TestWSGIServer.test_app_using_ssl
time: 2014-09-04 15:36:21.952500Z
successful: workloadmgr.tests.test_wsgi.TestWSGIServer.test_app_using_ssl [ multipart
Content-Type: text/plain;charset="utf8"
pythonlogging:''
DB
Started test_app on 0.0.0.0:38898
(27382) wsgi starting up on https://0.0.0.0:38898/

(27382) accepted ('127.0.0.1', 48399)

127.0.0.1 - - [04/Sep/2014 11:36:21] "GET / HTTP/1.1" 200 150 0.000170

Stopping WSGI server.
0
]
tags: -worker-0
time: 2014-09-04 15:36:21.952857Z
tags: worker-0
test: workloadmgr.tests.test_wsgi.TestWSGIServer.test_no_app
time: 2014-09-04 15:36:21.957366Z
successful: workloadmgr.tests.test_wsgi.TestWSGIServer.test_no_app [ multipart
]
tags: -worker-0
time: 2014-09-04 15:36:21.957581Z
tags: worker-0
test: workloadmgr.tests.test_wsgi.TestWSGIServer.test_start_random_port
time: 2014-09-04 15:36:21.961981Z
successful: workloadmgr.tests.test_wsgi.TestWSGIServer.test_start_random_port [ multipart
Content-Type: text/plain;charset="utf8"
pythonlogging:''
5B
Started test_random_port on 127.0.0.1:56234
Stopping WSGI server.
WSGI server has stopped.
0
]
tags: -worker-0
time: 2014-09-04 15:36:21.962277Z
tags: worker-0
test: workloadmgr.tests.test_wsgi.TestWSGIServer.test_start_random_port_with_ipv6
time: 2014-09-04 15:36:22.178399Z
failure: workloadmgr.tests.test_wsgi.TestWSGIServer.test_start_random_port_with_ipv6 [ multipart
Content-Type: text/x-traceback;charset="utf8",language="python"
traceback
568
Traceback (most recent call last):
_StringException: Empty attachments:
  pythonlogging:''
  pythonlogging:''-1
  stderr
  stdout

Traceback (most recent call last):
  File "workloadmgr/tests/test_wsgi.py", line 118, in test_start_random_port_with_ipv6
    server.start()
  File "workloadmgr/wsgi.py", line 191, in start
    backlog=backlog)
  File "workloadmgr/wsgi.py", line 141, in _get_socket
    family=family)
  File "/usr/local/lib/python2.7/dist-packages/eventlet/convenience.py", line 39, in listen
    sock.bind(addr)
  File "/usr/lib/python2.7/socket.py", line 224, in meth
    return getattr(self._sock,name)(*args)
gaierror: [Errno -9] Address family for hostname not supported

Traceback (most recent call last):
_StringException: Empty attachments:
  pythonlogging:''
  pythonlogging:''-1
  stderr
  stdout

Traceback (most recent call last):
  File "workloadmgr/tests/test_wsgi.py", line 118, in test_start_random_port_with_ipv6
    server.start()
  File "workloadmgr/wsgi.py", line 191, in start
    backlog=backlog)
  File "workloadmgr/wsgi.py", line 141, in _get_socket
    family=family)
  File "/usr/local/lib/python2.7/dist-packages/eventlet/convenience.py", line 39, in listen
    sock.bind(addr)
  File "/usr/lib/python2.7/socket.py", line 224, in meth
    return getattr(self._sock,name)(*args)
gaierror: [Errno -9] Address family for hostname not supported

0
]
tags: -worker-0
