time: 2014-09-21 18:42:11.350079Z
tags: worker-0
test: workloadmgr.tests.test_utils.ExecuteTestCase.test_check_exit_code_boolean
time: 2014-09-21 18:42:11.375971Z
failure: workloadmgr.tests.test_utils.ExecuteTestCase.test_check_exit_code_boolean [ multipart
Content-Type: text/x-traceback;charset=""utf8""
traceback
CC2
Traceback (most recent call last):
_StringException: Empty attachments:
  pythonlogging:''
  pythonlogging:''-1
  stderr
  stdout

Traceback (most recent call last):
  File "workloadmgr/tests/test_utils.py", line 97, in test_check_exit_code_boolean
    '/usr/bin/env', 'false', check_exit_code=True)
  File "/usr/local/lib/python2.7/dist-packages/testtools/testcase.py", line 420, in assertRaises
    self.assertThat(our_callable, matcher)
  File "/usr/local/lib/python2.7/dist-packages/testtools/testcase.py", line 431, in assertThat
    mismatch_error = self._matchHelper(matchee, matcher, message, verbose)
  File "/usr/local/lib/python2.7/dist-packages/testtools/testcase.py", line 481, in _matchHelper
    mismatch = matcher.match(matchee)
  File "/usr/local/lib/python2.7/dist-packages/testtools/matchers/_exception.py", line 108, in match
    mismatch = self.exception_matcher.match(exc_info)
  File "/usr/local/lib/python2.7/dist-packages/testtools/matchers/_higherorder.py", line 62, in match
    mismatch = matcher.match(matchee)
  File "/usr/local/lib/python2.7/dist-packages/testtools/testcase.py", line 412, in match
    reraise(*matchee)
  File "/usr/local/lib/python2.7/dist-packages/testtools/matchers/_exception.py", line 101, in match
    result = matchee()
  File "/usr/local/lib/python2.7/dist-packages/testtools/testcase.py", line 955, in __call__
    return self._callable_object(*self._args, **self._kwargs)
  File "workloadmgr/utils.py", line 187, in execute
    cmd=' '.join(cmd))
ProcessExecutionError: Unexpected error while running command.
Command: /usr/bin/env false
Exit code: 1
Stdout: ''
Stderr: ''

Traceback (most recent call last):
_StringException: Empty attachments:
  pythonlogging:''
  pythonlogging:''-1
  stderr
  stdout

Traceback (most recent call last):
  File "workloadmgr/tests/test_utils.py", line 97, in test_check_exit_code_boolean
    '/usr/bin/env', 'false', check_exit_code=True)
  File "/usr/local/lib/python2.7/dist-packages/testtools/testcase.py", line 420, in assertRaises
    self.assertThat(our_callable, matcher)
  File "/usr/local/lib/python2.7/dist-packages/testtools/testcase.py", line 431, in assertThat
    mismatch_error = self._matchHelper(matchee, matcher, message, verbose)
  File "/usr/local/lib/python2.7/dist-packages/testtools/testcase.py", line 481, in _matchHelper
    mismatch = matcher.match(matchee)
  File "/usr/local/lib/python2.7/dist-packages/testtools/matchers/_exception.py", line 108, in match
    mismatch = self.exception_matcher.match(exc_info)
  File "/usr/local/lib/python2.7/dist-packages/testtools/matchers/_higherorder.py", line 62, in match
    mismatch = matcher.match(matchee)
  File "/usr/local/lib/python2.7/dist-packages/testtools/testcase.py", line 412, in match
    reraise(*matchee)
  File "/usr/local/lib/python2.7/dist-packages/testtools/matchers/_exception.py", line 101, in match
    result = matchee()
  File "/usr/local/lib/python2.7/dist-packages/testtools/testcase.py", line 955, in __call__
    return self._callable_object(*self._args, **self._kwargs)
  File "workloadmgr/utils.py", line 187, in execute
    cmd=' '.join(cmd))
ProcessExecutionError: Unexpected error while running command.
Command: /usr/bin/env false
Exit code: 1
Stdout: ''
Stderr: ''

0
]
tags: -worker-0
time: 2014-09-21 18:42:11.456356Z
tags: worker-0
test: workloadmgr.tests.test_utils.ExecuteTestCase.test_retry_on_failure
time: 2014-09-21 18:42:11.603211Z
failure: workloadmgr.tests.test_utils.ExecuteTestCase.test_retry_on_failure [ multipart
Content-Type: text/x-traceback;charset=""utf8""
traceback
CC0
Traceback (most recent call last):
_StringException: Empty attachments:
  pythonlogging:''
  pythonlogging:''-1
  stderr
  stdout

Traceback (most recent call last):
  File "workloadmgr/tests/test_utils.py", line 74, in test_retry_on_failure
    delay_on_retry=False)
  File "/usr/local/lib/python2.7/dist-packages/testtools/testcase.py", line 420, in assertRaises
    self.assertThat(our_callable, matcher)
  File "/usr/local/lib/python2.7/dist-packages/testtools/testcase.py", line 431, in assertThat
    mismatch_error = self._matchHelper(matchee, matcher, message, verbose)
  File "/usr/local/lib/python2.7/dist-packages/testtools/testcase.py", line 481, in _matchHelper
    mismatch = matcher.match(matchee)
  File "/usr/local/lib/python2.7/dist-packages/testtools/matchers/_exception.py", line 108, in match
    mismatch = self.exception_matcher.match(exc_info)
  File "/usr/local/lib/python2.7/dist-packages/testtools/matchers/_higherorder.py", line 62, in match
    mismatch = matcher.match(matchee)
  File "/usr/local/lib/python2.7/dist-packages/testtools/testcase.py", line 412, in match
    reraise(*matchee)
  File "/usr/local/lib/python2.7/dist-packages/testtools/matchers/_exception.py", line 101, in match
    result = matchee()
  File "/usr/local/lib/python2.7/dist-packages/testtools/testcase.py", line 955, in __call__
    return self._callable_object(*self._args, **self._kwargs)
  File "workloadmgr/utils.py", line 187, in execute
    cmd=' '.join(cmd))
ProcessExecutionError: Unexpected error while running command.
Command: /tmp/tmpu9pUG8/tmpvUI46O /tmp/tmpu9pUG8/tmpuaGLRh
Exit code: 1
Stdout: ''
Stderr: ''

Traceback (most recent call last):
_StringException: Empty attachments:
  pythonlogging:''
  pythonlogging:''-1
  stderr
  stdout

Traceback (most recent call last):
  File "workloadmgr/tests/test_utils.py", line 74, in test_retry_on_failure
    delay_on_retry=False)
  File "/usr/local/lib/python2.7/dist-packages/testtools/testcase.py", line 420, in assertRaises
    self.assertThat(our_callable, matcher)
  File "/usr/local/lib/python2.7/dist-packages/testtools/testcase.py", line 431, in assertThat
    mismatch_error = self._matchHelper(matchee, matcher, message, verbose)
  File "/usr/local/lib/python2.7/dist-packages/testtools/testcase.py", line 481, in _matchHelper
    mismatch = matcher.match(matchee)
  File "/usr/local/lib/python2.7/dist-packages/testtools/matchers/_exception.py", line 108, in match
    mismatch = self.exception_matcher.match(exc_info)
  File "/usr/local/lib/python2.7/dist-packages/testtools/matchers/_higherorder.py", line 62, in match
    mismatch = matcher.match(matchee)
  File "/usr/local/lib/python2.7/dist-packages/testtools/testcase.py", line 412, in match
    reraise(*matchee)
  File "/usr/local/lib/python2.7/dist-packages/testtools/matchers/_exception.py", line 101, in match
    result = matchee()
  File "/usr/local/lib/python2.7/dist-packages/testtools/testcase.py", line 955, in __call__
    return self._callable_object(*self._args, **self._kwargs)
  File "workloadmgr/utils.py", line 187, in execute
    cmd=' '.join(cmd))
ProcessExecutionError: Unexpected error while running command.
Command: /tmp/tmpu9pUG8/tmpvUI46O /tmp/tmpu9pUG8/tmpuaGLRh
Exit code: 1
Stdout: ''
Stderr: ''

0
]
tags: -worker-0
time: 2014-09-21 18:42:11.603573Z
tags: worker-0
test: workloadmgr.tests.test_utils.ExecuteTestCase.test_unknown_kwargs_raises_error
time: 2014-09-21 18:42:11.610009Z
failure: workloadmgr.tests.test_utils.ExecuteTestCase.test_unknown_kwargs_raises_error [ multipart
Content-Type: text/x-traceback;charset=""utf8""
traceback
C7A
Traceback (most recent call last):
_StringException: Empty attachments:
  pythonlogging:''
  pythonlogging:''-1
  stderr
  stdout

Traceback (most recent call last):
  File "workloadmgr/tests/test_utils.py", line 91, in test_unknown_kwargs_raises_error
    this_is_not_a_valid_kwarg=True)
  File "/usr/local/lib/python2.7/dist-packages/testtools/testcase.py", line 420, in assertRaises
    self.assertThat(our_callable, matcher)
  File "/usr/local/lib/python2.7/dist-packages/testtools/testcase.py", line 431, in assertThat
    mismatch_error = self._matchHelper(matchee, matcher, message, verbose)
  File "/usr/local/lib/python2.7/dist-packages/testtools/testcase.py", line 481, in _matchHelper
    mismatch = matcher.match(matchee)
  File "/usr/local/lib/python2.7/dist-packages/testtools/matchers/_exception.py", line 108, in match
    mismatch = self.exception_matcher.match(exc_info)
  File "/usr/local/lib/python2.7/dist-packages/testtools/matchers/_higherorder.py", line 62, in match
    mismatch = matcher.match(matchee)
  File "/usr/local/lib/python2.7/dist-packages/testtools/testcase.py", line 412, in match
    reraise(*matchee)
  File "/usr/local/lib/python2.7/dist-packages/testtools/matchers/_exception.py", line 101, in match
    result = matchee()
  File "/usr/local/lib/python2.7/dist-packages/testtools/testcase.py", line 955, in __call__
    return self._callable_object(*self._args, **self._kwargs)
  File "workloadmgr/utils.py", line 142, in execute
    'to utils.execute: %r') % kwargs)
Error: Got unknown keyword args to utils.execute: {'this_is_not_a_valid_kwarg': True}

Traceback (most recent call last):
_StringException: Empty attachments:
  pythonlogging:''
  pythonlogging:''-1
  stderr
  stdout

Traceback (most recent call last):
  File "workloadmgr/tests/test_utils.py", line 91, in test_unknown_kwargs_raises_error
    this_is_not_a_valid_kwarg=True)
  File "/usr/local/lib/python2.7/dist-packages/testtools/testcase.py", line 420, in assertRaises
    self.assertThat(our_callable, matcher)
  File "/usr/local/lib/python2.7/dist-packages/testtools/testcase.py", line 431, in assertThat
    mismatch_error = self._matchHelper(matchee, matcher, message, verbose)
  File "/usr/local/lib/python2.7/dist-packages/testtools/testcase.py", line 481, in _matchHelper
    mismatch = matcher.match(matchee)
  File "/usr/local/lib/python2.7/dist-packages/testtools/matchers/_exception.py", line 108, in match
    mismatch = self.exception_matcher.match(exc_info)
  File "/usr/local/lib/python2.7/dist-packages/testtools/matchers/_higherorder.py", line 62, in match
    mismatch = matcher.match(matchee)
  File "/usr/local/lib/python2.7/dist-packages/testtools/testcase.py", line 412, in match
    reraise(*matchee)
  File "/usr/local/lib/python2.7/dist-packages/testtools/matchers/_exception.py", line 101, in match
    result = matchee()
  File "/usr/local/lib/python2.7/dist-packages/testtools/testcase.py", line 955, in __call__
    return self._callable_object(*self._args, **self._kwargs)
  File "workloadmgr/utils.py", line 142, in execute
    'to utils.execute: %r') % kwargs)
Error: Got unknown keyword args to utils.execute: {'this_is_not_a_valid_kwarg': True}

0
]
tags: -worker-0
time: 2014-09-21 18:42:11.615759Z
tags: worker-0
test: workloadmgr.tests.test_utils.GenericUtilsTestCase.test_check_ssh_injection_on_error
time: 2014-09-21 18:42:11.620954Z
failure: workloadmgr.tests.test_utils.GenericUtilsTestCase.test_check_ssh_injection_on_error [ multipart
Content-Type: text/x-traceback;charset=""utf8""
traceback
2F4
Traceback (most recent call last):
_StringException: Empty attachments:
  pythonlogging:''
  pythonlogging:''-1
  stderr
  stdout

Traceback (most recent call last):
  File "workloadmgr/tests/test_utils.py", line 464, in test_check_ssh_injection_on_error
    self.assertRaises(exception.SSHInjectionThreat,
AttributeError: 'module' object has no attribute 'SSHInjectionThreat'

Traceback (most recent call last):
_StringException: Empty attachments:
  pythonlogging:''
  pythonlogging:''-1
  stderr
  stdout

Traceback (most recent call last):
  File "workloadmgr/tests/test_utils.py", line 464, in test_check_ssh_injection_on_error
    self.assertRaises(exception.SSHInjectionThreat,
AttributeError: 'module' object has no attribute 'SSHInjectionThreat'

0
]
tags: -worker-0
time: 2014-09-21 18:42:11.625760Z
tags: worker-0
test: workloadmgr.tests.test_utils.GenericUtilsTestCase.test_generate_glance_url
time: 2014-09-21 18:42:11.630436Z
failure: workloadmgr.tests.test_utils.GenericUtilsTestCase.test_generate_glance_url [ multipart
Content-Type: text/x-traceback;charset=""utf8""
traceback
2DC
Traceback (most recent call last):
_StringException: Empty attachments:
  pythonlogging:''
  pythonlogging:''-1
  stderr
  stdout

Traceback (most recent call last):
  File "workloadmgr/tests/test_utils.py", line 304, in test_generate_glance_url
    generated_url = utils.generate_glance_url()
AttributeError: 'module' object has no attribute 'generate_glance_url'

Traceback (most recent call last):
_StringException: Empty attachments:
  pythonlogging:''
  pythonlogging:''-1
  stderr
  stdout

Traceback (most recent call last):
  File "workloadmgr/tests/test_utils.py", line 304, in test_generate_glance_url
    generated_url = utils.generate_glance_url()
AttributeError: 'module' object has no attribute 'generate_glance_url'

0
]
tags: -worker-0
time: 2014-09-21 18:42:11.639488Z
tags: worker-0
test: workloadmgr.tests.test_utils.GenericUtilsTestCase.test_get_file_mode
time: 2014-09-21 18:42:11.643850Z
failure: workloadmgr.tests.test_utils.GenericUtilsTestCase.test_get_file_mode [ multipart
Content-Type: text/x-traceback;charset=""utf8""
traceback
364
Traceback (most recent call last):
_StringException: Empty attachments:
  pythonlogging:''
  pythonlogging:''-1
  stderr
  stdout

Traceback (most recent call last):
  File "workloadmgr/tests/test_utils.py", line 543, in test_get_file_mode
    mode = utils.get_file_mode(test_file)
  File "workloadmgr/utils.py", line 1256, in get_file_mode
    return stat.S_IMODE(os.stat(path).st_mode)
NameError: global name 'stat' is not defined

Traceback (most recent call last):
_StringException: Empty attachments:
  pythonlogging:''
  pythonlogging:''-1
  stderr
  stdout

Traceback (most recent call last):
  File "workloadmgr/tests/test_utils.py", line 543, in test_get_file_mode
    mode = utils.get_file_mode(test_file)
  File "workloadmgr/utils.py", line 1256, in get_file_mode
    return stat.S_IMODE(os.stat(path).st_mode)
NameError: global name 'stat' is not defined

0
]
tags: -worker-0
time: 2014-09-21 18:42:11.674250Z
tags: worker-0
test: workloadmgr.tests.test_utils.GenericUtilsTestCase.test_read_file_as_root
time: 2014-09-21 18:42:11.679146Z
failure: workloadmgr.tests.test_utils.GenericUtilsTestCase.test_read_file_as_root [ multipart
Content-Type: text/x-traceback;charset=""utf8""
traceback
DBA
Traceback (most recent call last):
_StringException: Empty attachments:
  pythonlogging:''
  pythonlogging:''-1
  stderr
  stdout

Traceback (most recent call last):
  File "workloadmgr/tests/test_utils.py", line 366, in test_read_file_as_root
    utils.read_file_as_root, 'bad')
  File "/usr/local/lib/python2.7/dist-packages/testtools/testcase.py", line 420, in assertRaises
    self.assertThat(our_callable, matcher)
  File "/usr/local/lib/python2.7/dist-packages/testtools/testcase.py", line 431, in assertThat
    mismatch_error = self._matchHelper(matchee, matcher, message, verbose)
  File "/usr/local/lib/python2.7/dist-packages/testtools/testcase.py", line 481, in _matchHelper
    mismatch = matcher.match(matchee)
  File "/usr/local/lib/python2.7/dist-packages/testtools/matchers/_exception.py", line 108, in match
    mismatch = self.exception_matcher.match(exc_info)
  File "/usr/local/lib/python2.7/dist-packages/testtools/matchers/_higherorder.py", line 62, in match
    mismatch = matcher.match(matchee)
  File "/usr/local/lib/python2.7/dist-packages/testtools/testcase.py", line 412, in match
    reraise(*matchee)
  File "/usr/local/lib/python2.7/dist-packages/testtools/matchers/_exception.py", line 101, in match
    result = matchee()
  File "/usr/local/lib/python2.7/dist-packages/testtools/testcase.py", line 955, in __call__
    return self._callable_object(*self._args, **self._kwargs)
  File "workloadmgr/utils.py", line 921, in read_file_as_root
    out, _err = execute('cat', file_path, run_as_root=True)
  File "workloadmgr/tests/test_utils.py", line 359, in fake_execute
    raise putils.ProcessExecutionError
ProcessExecutionError: Unexpected error while running command.
Command: None
Exit code: -
Stdout: None
Stderr: None

Traceback (most recent call last):
_StringException: Empty attachments:
  pythonlogging:''
  pythonlogging:''-1
  stderr
  stdout

Traceback (most recent call last):
  File "workloadmgr/tests/test_utils.py", line 366, in test_read_file_as_root
    utils.read_file_as_root, 'bad')
  File "/usr/local/lib/python2.7/dist-packages/testtools/testcase.py", line 420, in assertRaises
    self.assertThat(our_callable, matcher)
  File "/usr/local/lib/python2.7/dist-packages/testtools/testcase.py", line 431, in assertThat
    mismatch_error = self._matchHelper(matchee, matcher, message, verbose)
  File "/usr/local/lib/python2.7/dist-packages/testtools/testcase.py", line 481, in _matchHelper
    mismatch = matcher.match(matchee)
  File "/usr/local/lib/python2.7/dist-packages/testtools/matchers/_exception.py", line 108, in match
    mismatch = self.exception_matcher.match(exc_info)
  File "/usr/local/lib/python2.7/dist-packages/testtools/matchers/_higherorder.py", line 62, in match
    mismatch = matcher.match(matchee)
  File "/usr/local/lib/python2.7/dist-packages/testtools/testcase.py", line 412, in match
    reraise(*matchee)
  File "/usr/local/lib/python2.7/dist-packages/testtools/matchers/_exception.py", line 101, in match
    result = matchee()
  File "/usr/local/lib/python2.7/dist-packages/testtools/testcase.py", line 955, in __call__
    return self._callable_object(*self._args, **self._kwargs)
  File "workloadmgr/utils.py", line 921, in read_file_as_root
    out, _err = execute('cat', file_path, run_as_root=True)
  File "workloadmgr/tests/test_utils.py", line 359, in fake_execute
    raise putils.ProcessExecutionError
ProcessExecutionError: Unexpected error while running command.
Command: None
Exit code: -
Stdout: None
Stderr: None

0
]
tags: -worker-0
time: 2014-09-21 18:42:11.753793Z
tags: worker-0
test: workloadmgr.tests.test_workload_type.BaseWorkloadTypeTestCase.test_create_delete_workload_type
time: 2014-09-21 18:42:11.908228Z
failure: workloadmgr.tests.test_workload_type.BaseWorkloadTypeTestCase.test_create_delete_workload_type [ multipart
Content-Type: text/x-traceback;charset=""utf8""
traceback
608
Traceback (most recent call last):
_StringException: Empty attachments:
  pythonlogging:''-1
  stderr
  stdout

pythonlogging:'': {{{
Started thread pool with 0 core threads and 20 maximum threads
Scheduler started
Started thread pool with 0 core threads and 20 maximum threads
Scheduler started
}}}

Traceback (most recent call last):
  File "workloadmgr/tests/test_workload_type.py", line 65, in test_create_delete_workload_type
    self.assertEqual(workload_type['metadata'], {})
  File "/usr/local/lib/python2.7/dist-packages/testtools/testcase.py", line 348, in assertEqual
    self.assertThat(observed, matcher, message)
  File "/usr/local/lib/python2.7/dist-packages/testtools/testcase.py", line 433, in assertThat
    raise mismatch_error
MismatchError: [] != {}

Traceback (most recent call last):
_StringException: Empty attachments:
  pythonlogging:''-1
  stderr
  stdout

pythonlogging:'': {{{
Started thread pool with 0 core threads and 20 maximum threads
Scheduler started
Started thread pool with 0 core threads and 20 maximum threads
Scheduler started
}}}

Traceback (most recent call last):
  File "workloadmgr/tests/test_workload_type.py", line 65, in test_create_delete_workload_type
    self.assertEqual(workload_type['metadata'], {})
  File "/usr/local/lib/python2.7/dist-packages/testtools/testcase.py", line 348, in assertEqual
    self.assertThat(observed, matcher, message)
  File "/usr/local/lib/python2.7/dist-packages/testtools/testcase.py", line 433, in assertThat
    raise mismatch_error
MismatchError: [] != {}

0
]
tags: -worker-0
time: 2014-09-21 18:42:11.908550Z
tags: worker-0
test: workloadmgr.tests.test_workload_type.BaseWorkloadTypeTestCase.test_create_workload_type_invalid_metadata
time: 2014-09-21 18:42:11.927137Z
failure: workloadmgr.tests.test_workload_type.BaseWorkloadTypeTestCase.test_create_workload_type_invalid_metadata [ multipart
Content-Type: text/x-traceback;charset=""utf8""
traceback
57A
Traceback (most recent call last):
_StringException: Empty attachments:
  pythonlogging:''-1
  stderr
  stdout

pythonlogging:'': {{{
Started thread pool with 0 core threads and 20 maximum threads
Scheduler started
}}}

Traceback (most recent call last):
  File "workloadmgr/tests/test_workload_type.py", line 98, in test_create_workload_type_invalid_metadata
    self.assertEqual(workload_type['metadata'], {})
  File "/usr/local/lib/python2.7/dist-packages/testtools/testcase.py", line 348, in assertEqual
    self.assertThat(observed, matcher, message)
  File "/usr/local/lib/python2.7/dist-packages/testtools/testcase.py", line 433, in assertThat
    raise mismatch_error
MismatchError: [] != {}

Traceback (most recent call last):
_StringException: Empty attachments:
  pythonlogging:''-1
  stderr
  stdout

pythonlogging:'': {{{
Started thread pool with 0 core threads and 20 maximum threads
Scheduler started
}}}

Traceback (most recent call last):
  File "workloadmgr/tests/test_workload_type.py", line 98, in test_create_workload_type_invalid_metadata
    self.assertEqual(workload_type['metadata'], {})
  File "/usr/local/lib/python2.7/dist-packages/testtools/testcase.py", line 348, in assertEqual
    self.assertThat(observed, matcher, message)
  File "/usr/local/lib/python2.7/dist-packages/testtools/testcase.py", line 433, in assertThat
    raise mismatch_error
MismatchError: [] != {}

0
]
tags: -worker-0
time: 2014-09-21 18:42:58.945239Z
tags: worker-0
test: workloadmgr.tests.test_workload_type_cassandra.BaseWorkloadTypeCassandraTestCase.test_create_delete_workload_type
time: 2014-09-21 18:42:59.005533Z
failure: workloadmgr.tests.test_workload_type_cassandra.BaseWorkloadTypeCassandraTestCase.test_create_delete_workload_type [ multipart
Content-Type: text/x-traceback;charset=""utf8""
traceback
616
Traceback (most recent call last):
_StringException: Empty attachments:
  pythonlogging:''-1
  stderr
  stdout

pythonlogging:'': {{{
Started thread pool with 0 core threads and 20 maximum threads
Scheduler started
}}}

Traceback (most recent call last):
  File "workloadmgr/tests/test_workload_type_cassandra.py", line 216, in test_create_delete_workload_type
    workload_type_id)
  File "/usr/local/lib/python2.7/dist-packages/testtools/testcase.py", line 420, in assertRaises
    self.assertThat(our_callable, matcher)
  File "/usr/local/lib/python2.7/dist-packages/testtools/testcase.py", line 433, in assertThat
    raise mismatch_error
MismatchError: <function workload_type_get at 0x2b806e0> returned <workloadmgr.db.sqlalchemy.models.WorkloadTypes object at 0x533d2d0>

Traceback (most recent call last):
_StringException: Empty attachments:
  pythonlogging:''-1
  stderr
  stdout

pythonlogging:'': {{{
Started thread pool with 0 core threads and 20 maximum threads
Scheduler started
}}}

Traceback (most recent call last):
  File "workloadmgr/tests/test_workload_type_cassandra.py", line 216, in test_create_delete_workload_type
    workload_type_id)
  File "/usr/local/lib/python2.7/dist-packages/testtools/testcase.py", line 420, in assertRaises
    self.assertThat(our_callable, matcher)
  File "/usr/local/lib/python2.7/dist-packages/testtools/testcase.py", line 433, in assertThat
    raise mismatch_error
MismatchError: <function workload_type_get at 0x2b806e0> returned <workloadmgr.db.sqlalchemy.models.WorkloadTypes object at 0x533d2d0>

0
]
tags: -worker-0
time: 2014-09-21 18:42:59.005902Z
tags: worker-0
test: workloadmgr.tests.test_workload_type_cassandra.BaseWorkloadTypeCassandraTestCase.test_create_workload_type_invalid_metadata
time: 2014-09-21 18:42:59.046410Z
failure: workloadmgr.tests.test_workload_type_cassandra.BaseWorkloadTypeCassandraTestCase.test_create_workload_type_invalid_metadata [ multipart
Content-Type: text/x-traceback;charset=""utf8""
traceback
62A
Traceback (most recent call last):
_StringException: Empty attachments:
  pythonlogging:''-1
  stderr
  stdout

pythonlogging:'': {{{
Started thread pool with 0 core threads and 20 maximum threads
Scheduler started
}}}

Traceback (most recent call last):
  File "workloadmgr/tests/test_workload_type_cassandra.py", line 248, in test_create_workload_type_invalid_metadata
    workload_type_id)
  File "/usr/local/lib/python2.7/dist-packages/testtools/testcase.py", line 420, in assertRaises
    self.assertThat(our_callable, matcher)
  File "/usr/local/lib/python2.7/dist-packages/testtools/testcase.py", line 433, in assertThat
    raise mismatch_error
MismatchError: <function workload_type_get at 0x2b806e0> returned <workloadmgr.db.sqlalchemy.models.WorkloadTypes object at 0x5515d90>

Traceback (most recent call last):
_StringException: Empty attachments:
  pythonlogging:''-1
  stderr
  stdout

pythonlogging:'': {{{
Started thread pool with 0 core threads and 20 maximum threads
Scheduler started
}}}

Traceback (most recent call last):
  File "workloadmgr/tests/test_workload_type_cassandra.py", line 248, in test_create_workload_type_invalid_metadata
    workload_type_id)
  File "/usr/local/lib/python2.7/dist-packages/testtools/testcase.py", line 420, in assertRaises
    self.assertThat(our_callable, matcher)
  File "/usr/local/lib/python2.7/dist-packages/testtools/testcase.py", line 433, in assertThat
    raise mismatch_error
MismatchError: <function workload_type_get at 0x2b806e0> returned <workloadmgr.db.sqlalchemy.models.WorkloadTypes object at 0x5515d90>

0
]
tags: -worker-0
time: 2014-09-21 18:42:59.046767Z
tags: worker-0
test: workloadmgr.tests.test_workload_type_mongodb.BaseWorkloadTypeMongoDBTestCase.test_create_delete_workload_type
time: 2014-09-21 18:42:59.118523Z
failure: workloadmgr.tests.test_workload_type_mongodb.BaseWorkloadTypeMongoDBTestCase.test_create_delete_workload_type [ multipart
Content-Type: text/x-traceback;charset=""utf8""
traceback
612
Traceback (most recent call last):
_StringException: Empty attachments:
  pythonlogging:''-1
  stderr
  stdout

pythonlogging:'': {{{
Started thread pool with 0 core threads and 20 maximum threads
Scheduler started
}}}

Traceback (most recent call last):
  File "workloadmgr/tests/test_workload_type_mongodb.py", line 161, in test_create_delete_workload_type
    workload_type_id)
  File "/usr/local/lib/python2.7/dist-packages/testtools/testcase.py", line 420, in assertRaises
    self.assertThat(our_callable, matcher)
  File "/usr/local/lib/python2.7/dist-packages/testtools/testcase.py", line 433, in assertThat
    raise mismatch_error
MismatchError: <function workload_type_get at 0x2b806e0> returned <workloadmgr.db.sqlalchemy.models.WorkloadTypes object at 0x52cc890>

Traceback (most recent call last):
_StringException: Empty attachments:
  pythonlogging:''-1
  stderr
  stdout

pythonlogging:'': {{{
Started thread pool with 0 core threads and 20 maximum threads
Scheduler started
}}}

Traceback (most recent call last):
  File "workloadmgr/tests/test_workload_type_mongodb.py", line 161, in test_create_delete_workload_type
    workload_type_id)
  File "/usr/local/lib/python2.7/dist-packages/testtools/testcase.py", line 420, in assertRaises
    self.assertThat(our_callable, matcher)
  File "/usr/local/lib/python2.7/dist-packages/testtools/testcase.py", line 433, in assertThat
    raise mismatch_error
MismatchError: <function workload_type_get at 0x2b806e0> returned <workloadmgr.db.sqlalchemy.models.WorkloadTypes object at 0x52cc890>

0
]
tags: -worker-0
time: 2014-09-21 18:42:59.118856Z
tags: worker-0
test: workloadmgr.tests.test_workload_type_mongodb.BaseWorkloadTypeMongoDBTestCase.test_create_workload_type_invalid_metadata
time: 2014-09-21 18:42:59.159000Z
failure: workloadmgr.tests.test_workload_type_mongodb.BaseWorkloadTypeMongoDBTestCase.test_create_workload_type_invalid_metadata [ multipart
Content-Type: text/x-traceback;charset=""utf8""
traceback
626
Traceback (most recent call last):
_StringException: Empty attachments:
  pythonlogging:''-1
  stderr
  stdout

pythonlogging:'': {{{
Started thread pool with 0 core threads and 20 maximum threads
Scheduler started
}}}

Traceback (most recent call last):
  File "workloadmgr/tests/test_workload_type_mongodb.py", line 193, in test_create_workload_type_invalid_metadata
    workload_type_id)
  File "/usr/local/lib/python2.7/dist-packages/testtools/testcase.py", line 420, in assertRaises
    self.assertThat(our_callable, matcher)
  File "/usr/local/lib/python2.7/dist-packages/testtools/testcase.py", line 433, in assertThat
    raise mismatch_error
MismatchError: <function workload_type_get at 0x2b806e0> returned <workloadmgr.db.sqlalchemy.models.WorkloadTypes object at 0x535a950>

Traceback (most recent call last):
_StringException: Empty attachments:
  pythonlogging:''-1
  stderr
  stdout

pythonlogging:'': {{{
Started thread pool with 0 core threads and 20 maximum threads
Scheduler started
}}}

Traceback (most recent call last):
  File "workloadmgr/tests/test_workload_type_mongodb.py", line 193, in test_create_workload_type_invalid_metadata
    workload_type_id)
  File "/usr/local/lib/python2.7/dist-packages/testtools/testcase.py", line 420, in assertRaises
    self.assertThat(our_callable, matcher)
  File "/usr/local/lib/python2.7/dist-packages/testtools/testcase.py", line 433, in assertThat
    raise mismatch_error
MismatchError: <function workload_type_get at 0x2b806e0> returned <workloadmgr.db.sqlalchemy.models.WorkloadTypes object at 0x535a950>

0
]
tags: -worker-0
time: 2014-09-21 18:43:44.699784Z
tags: worker-0
test: workloadmgr.tests.test_workload_type_mongodb.BaseWorkloadTypeMongoDBTestCase.test_mongodb_secondary_hosts_to_backup
time: 2014-09-21 18:43:44.708285Z
failure: workloadmgr.tests.test_workload_type_mongodb.BaseWorkloadTypeMongoDBTestCase.test_mongodb_secondary_hosts_to_backup [ multipart
Content-Type: text/x-traceback;charset=""utf8""
traceback
7C4
Traceback (most recent call last):
_StringException: Empty attachments:
  pythonlogging:''-1
  stdout

pythonlogging:'': {{{
Started thread pool with 0 core threads and 20 maximum threads
Scheduler started
}}}

stderr: {{{
workloadmgr/tests/test_workload_type_mongodb.py:446: DeprecationWarning: With-statements now directly support multiple context managers
  mock.patch('pymongo.database.Database')
}}}

Traceback (most recent call last):
  File "/usr/local/lib/python2.7/dist-packages/mock.py", line 1201, in patched
    return func(*args, **keywargs)
  File "workloadmgr/tests/test_workload_type_mongodb.py", line 473, in test_mongodb_secondary_hosts_to_backup
    self.assertEqual(len(hosts), replnum)
  File "/usr/local/lib/python2.7/dist-packages/testtools/testcase.py", line 348, in assertEqual
    self.assertThat(observed, matcher, message)
  File "/usr/local/lib/python2.7/dist-packages/testtools/testcase.py", line 433, in assertThat
    raise mismatch_error
MismatchError: 3 != 4

Traceback (most recent call last):
_StringException: Empty attachments:
  pythonlogging:''-1
  stdout

pythonlogging:'': {{{
Started thread pool with 0 core threads and 20 maximum threads
Scheduler started
}}}

stderr: {{{
workloadmgr/tests/test_workload_type_mongodb.py:446: DeprecationWarning: With-statements now directly support multiple context managers
  mock.patch('pymongo.database.Database')
}}}

Traceback (most recent call last):
  File "/usr/local/lib/python2.7/dist-packages/mock.py", line 1201, in patched
    return func(*args, **keywargs)
  File "workloadmgr/tests/test_workload_type_mongodb.py", line 473, in test_mongodb_secondary_hosts_to_backup
    self.assertEqual(len(hosts), replnum)
  File "/usr/local/lib/python2.7/dist-packages/testtools/testcase.py", line 348, in assertEqual
    self.assertThat(observed, matcher, message)
  File "/usr/local/lib/python2.7/dist-packages/testtools/testcase.py", line 433, in assertThat
    raise mismatch_error
MismatchError: 3 != 4

0
]
tags: -worker-0
time: 2014-09-21 18:43:44.722226Z
tags: worker-0
test: workloadmgr.tests.test_workloads.BaseWorkloadTestCase.test_create_delete_workload
time: 2014-09-21 18:43:44.796995Z
failure: workloadmgr.tests.test_workloads.BaseWorkloadTestCase.test_create_delete_workload [ multipart
Content-Type: text/x-traceback;charset=""utf8""
traceback
A82
Traceback (most recent call last):
_StringException: Empty attachments:
  pythonlogging:''-1
  stderr
  stdout

pythonlogging:'': {{{
Started thread pool with 0 core threads and 20 maximum threads
Scheduler started
[0m [0;33mWorkloadMgrManager.workload_create[0;35m ENTER [0m(<workloadmgr.workloads.manager.WorkloadMgrManager object at 0x56bee10>, <workloadmgr.context.RequestContext object at 0x56c05d0>, e17c441a-8fac-49fa-8632-00136696d9e2)
[0m [0;33mWorkloadMgrManager.workload_create[0;34m EXIT [0m(Return Value(s):None)
[0m [0;33mworkload_delete[0;35m ENTER [0m(<workloadmgr.workloads.manager.WorkloadMgrManager object at 0x56bee10>, <workloadmgr.context.RequestContext object at 0x56c05d0>, e17c441a-8fac-49fa-8632-00136696d9e2)
[0m [0;33mworkload_delete[0;34m EXIT [0m(Return Value(s):None)
}}}

Traceback (most recent call last):
  File "workloadmgr/tests/test_workloads.py", line 74, in test_create_delete_workload
    workload_id)
  File "/usr/local/lib/python2.7/dist-packages/testtools/testcase.py", line 420, in assertRaises
    self.assertThat(our_callable, matcher)
  File "/usr/local/lib/python2.7/dist-packages/testtools/testcase.py", line 433, in assertThat
    raise mismatch_error
MismatchError: <function workload_get at 0x2b807d0> returned <workloadmgr.db.sqlalchemy.models.Workloads object at 0x56293d0>

Traceback (most recent call last):
_StringException: Empty attachments:
  pythonlogging:''-1
  stderr
  stdout

pythonlogging:'': {{{
Started thread pool with 0 core threads and 20 maximum threads
Scheduler started
[0m [0;33mWorkloadMgrManager.workload_create[0;35m ENTER [0m(<workloadmgr.workloads.manager.WorkloadMgrManager object at 0x56bee10>, <workloadmgr.context.RequestContext object at 0x56c05d0>, e17c441a-8fac-49fa-8632-00136696d9e2)
[0m [0;33mWorkloadMgrManager.workload_create[0;34m EXIT [0m(Return Value(s):None)
[0m [0;33mworkload_delete[0;35m ENTER [0m(<workloadmgr.workloads.manager.WorkloadMgrManager object at 0x56bee10>, <workloadmgr.context.RequestContext object at 0x56c05d0>, e17c441a-8fac-49fa-8632-00136696d9e2)
[0m [0;33mworkload_delete[0;34m EXIT [0m(Return Value(s):None)
}}}

Traceback (most recent call last):
  File "workloadmgr/tests/test_workloads.py", line 74, in test_create_delete_workload
    workload_id)
  File "/usr/local/lib/python2.7/dist-packages/testtools/testcase.py", line 420, in assertRaises
    self.assertThat(our_callable, matcher)
  File "/usr/local/lib/python2.7/dist-packages/testtools/testcase.py", line 433, in assertThat
    raise mismatch_error
MismatchError: <function workload_get at 0x2b807d0> returned <workloadmgr.db.sqlalchemy.models.Workloads object at 0x56293d0>

0
]
tags: -worker-0
